Workbook

Sheet Фундаментальные
A1: L0 | C1: L1 | E1: L2 | G1: L3 | I1: L4 | K1: L5 | M1: Уровень* | N1: Макс. | O1: Оцениваемый пункт | P1: Комментарий
A2: ООП | B2: =AVERAGE(D2:D6) -> 1 | C2: Полиморфизм | D2: =AVERAGE(F2:F3) -> 1 | E2: параметрический полиморфизм | F2: =M2/N2 -> 1 | H2: =M2/N2 -> 1 | J2: =M2/N2 -> 1 | L2: =M2/N2 -> 1 | M2: 1 | N2: 1 | O2: =IFS(NOT(ISBLANK(K2)),K2,NOT(ISBLANK(I2)),I2,NOT(ISBLANK(G2)),G2,NOT(ISBLANK(E2)),E2,NOT(ISBLANK(C2)),C2,NOT(ISBLANK(A2)),A2) -> параметрический полиморфизм
E3: ad-hoc полиморфизм | F3: =M3/N3 -> 1 | H3: =M3/N3 -> 1 | J3: =M3/N3 -> 1 | L3: =M3/N3 -> 1 | M3: 1 | N3: 1 | O3: =IFS(NOT(ISBLANK(K3)),K3,NOT(ISBLANK(I3)),I3,NOT(ISBLANK(G3)),G3,NOT(ISBLANK(E3)),E3,NOT(ISBLANK(C3)),C3,NOT(ISBLANK(A3)),A3) -> ad-hoc полиморфизм
C4: Инкапсуляция | D4: =F4 -> 1 | F4: =M4/N4 -> 1 | H4: =M4/N4 -> 1 | J4: =M4/N4 -> 1 | L4: =M4/N4 -> 1 | M4: 1 | N4: 1 | O4: =IFS(NOT(ISBLANK(K4)),K4,NOT(ISBLANK(I4)),I4,NOT(ISBLANK(G4)),G4,NOT(ISBLANK(E4)),E4,NOT(ISBLANK(C4)),C4,NOT(ISBLANK(A4)),A4) -> Инкапсуляция
C5: Наследование | D5: =F5 -> 1 | F5: =M5/N5 -> 1 | H5: =M5/N5 -> 1 | J5: =M5/N5 -> 1 | L5: =M5/N5 -> 1 | M5: 1 | N5: 1 | O5: =IFS(NOT(ISBLANK(K5)),K5,NOT(ISBLANK(I5)),I5,NOT(ISBLANK(G5)),G5,NOT(ISBLANK(E5)),E5,NOT(ISBLANK(C5)),C5,NOT(ISBLANK(A5)),A5) -> Наследование
C6: Абстракция | D6: =F6 -> 1 | F6: =M6/N6 -> 1 | H6: =M6/N6 -> 1 | J6: =M6/N6 -> 1 | L6: =M6/N6 -> 1 | M6: 1 | N6: 1 | O6: =IFS(NOT(ISBLANK(K6)),K6,NOT(ISBLANK(I6)),I6,NOT(ISBLANK(G6)),G6,NOT(ISBLANK(E6)),E6,NOT(ISBLANK(C6)),C6,NOT(ISBLANK(A6)),A6) -> Абстракция
A7: SOLID | B7: =D7 -> 0.6 | D7: =F7 -> 0.6 | F7: =M7/N7 -> 0.6 | H7: =M7/N7 -> 0.6 | J7: =M7/N7 -> 0.6 | L7: =M7/N7 -> 0.6 | M7: 6 | N7: 10 | O7: =IFS(NOT(ISBLANK(K7)),K7,NOT(ISBLANK(I7)),I7,NOT(ISBLANK(G7)),G7,NOT(ISBLANK(E7)),E7,NOT(ISBLANK(C7)),C7,NOT(ISBLANK(A7)),A7) -> SOLID
A8: KISS | B8: =D8 -> 0.6 | D8: =F8 -> 0.6 | F8: =M8/N8 -> 0.6 | H8: =M8/N8 -> 0.6 | J8: =M8/N8 -> 0.6 | L8: =M8/N8 -> 0.6 | M8: 6 | N8: 10 | O8: =IFS(NOT(ISBLANK(K8)),K8,NOT(ISBLANK(I8)),I8,NOT(ISBLANK(G8)),G8,NOT(ISBLANK(E8)),E8,NOT(ISBLANK(C8)),C8,NOT(ISBLANK(A8)),A8) -> KISS
A9: Функциональное программирование | B9: =D9 -> 0.3 | D9: =F9 -> 0.3 | F9: =M9/N9 -> 0.3 | H9: =M9/N9 -> 0.3 | J9: =M9/N9 -> 0.3 | L9: =M9/N9 -> 0.3 | M9: 3 | N9: 10 | O9: =IFS(NOT(ISBLANK(K9)),K9,NOT(ISBLANK(I9)),I9,NOT(ISBLANK(G9)),G9,NOT(ISBLANK(E9)),E9,NOT(ISBLANK(C9)),C9,NOT(ISBLANK(A9)),A9) -> Функциональное программирование
A10: Алгоритмы | B10: =D10 -> 0.3 | D10: =F10 -> 0.3 | F10: =M10/N10 -> 0.3 | H10: =M10/N10 -> 0.3 | J10: =M10/N10 -> 0.3 | L10: =M10/N10 -> 0.3 | M10: 3 | N10: 10 | O10: =IFS(NOT(ISBLANK(K10)),K10,NOT(ISBLANK(I10)),I10,NOT(ISBLANK(G10)),G10,NOT(ISBLANK(E10)),E10,NOT(ISBLANK(C10)),C10,NOT(ISBLANK(A10)),A10) -> Алгоритмы
A11: Паттерны проектирования | B11: =D11 -> 0.5 | D11: =F11 -> 0.5 | F11: =M11/N11 -> 0.5 | H11: =M11/N11 -> 0.5 | J11: =M11/N11 -> 0.5 | L11: =M11/N11 -> 0.5 | M11: 5 | N11: 10 | O11: =IFS(NOT(ISBLANK(K11)),K11,NOT(ISBLANK(I11)),I11,NOT(ISBLANK(G11)),G11,NOT(ISBLANK(E11)),E11,NOT(ISBLANK(C11)),C11,NOT(ISBLANK(A11)),A11) -> Паттерны проектирования
A12: Паттерны архитектуры | B12: =D12 -> 0.3 | D12: =F12 -> 0.3 | F12: =M12/N12 -> 0.3 | H12: =M12/N12 -> 0.3 | J12: =M12/N12 -> 0.3 | L12: =M12/N12 -> 0.3 | M12: 3 | N12: 10 | O12: =IFS(NOT(ISBLANK(K12)),K12,NOT(ISBLANK(I12)),I12,NOT(ISBLANK(G12)),G12,NOT(ISBLANK(E12)),E12,NOT(ISBLANK(C12)),C12,NOT(ISBLANK(A12)),A12) -> Паттерны архитектуры
A13: DI | B13: =D13 -> 0.3 | D13: =F13 -> 0.3 | F13: =M13/N13 -> 0.3 | H13: =M13/N13 -> 0.3 | J13: =M13/N13 -> 0.3 | L13: =M13/N13 -> 0.3 | M13: 3 | N13: 10 | O13: =IFS(NOT(ISBLANK(K13)),K13,NOT(ISBLANK(I13)),I13,NOT(ISBLANK(G13)),G13,NOT(ISBLANK(E13)),E13,NOT(ISBLANK(C13)),C13,NOT(ISBLANK(A13)),A13) -> DI
A14: Навыки проектирования | B14: =D14 -> 0.3 | D14: =F14 -> 0.3 | F14: =M14/N14 -> 0.3 | H14: =M14/N14 -> 0.3 | J14: =M14/N14 -> 0.3 | L14: =M14/N14 -> 0.3 | M14: 3 | N14: 10 | O14: =IFS(NOT(ISBLANK(K14)),K14,NOT(ISBLANK(I14)),I14,NOT(ISBLANK(G14)),G14,NOT(ISBLANK(E14)),E14,NOT(ISBLANK(C14)),C14,NOT(ISBLANK(A14)),A14) -> Навыки проектирования
A15: Подходы в разработке | B15: =AVERAGE(D15:D17) -> 0.3 | C15: BDD | D15: =F15 -> 0.3 | F15: =M15/N15 -> 0.3 | H15: =M15/N15 -> 0.3 | J15: =M15/N15 -> 0.3 | L15: =M15/N15 -> 0.3 | M15: 3 | N15: 10 | O15: =IFS(NOT(ISBLANK(K15)),K15,NOT(ISBLANK(I15)),I15,NOT(ISBLANK(G15)),G15,NOT(ISBLANK(E15)),E15,NOT(ISBLANK(C15)),C15,NOT(ISBLANK(A15)),A15) -> BDD
C16: FDD | D16: =F16 -> 0.3 | F16: =M16/N16 -> 0.3 | H16: =M16/N16 -> 0.3 | J16: =M16/N16 -> 0.3 | L16: =M16/N16 -> 0.3 | M16: 3 | N16: 10 | O16: =IFS(NOT(ISBLANK(K16)),K16,NOT(ISBLANK(I16)),I16,NOT(ISBLANK(G16)),G16,NOT(ISBLANK(E16)),E16,NOT(ISBLANK(C16)),C16,NOT(ISBLANK(A16)),A16) -> FDD
C17: DDD | D17: =F17 -> 0.3 | F17: =M17/N17 -> 0.3 | H17: =M17/N17 -> 0.3 | J17: =M17/N17 -> 0.3 | L17: =M17/N17 -> 0.3 | M17: 3 | N17: 10 | O17: =IFS(NOT(ISBLANK(K17)),K17,NOT(ISBLANK(I17)),I17,NOT(ISBLANK(G17)),G17,NOT(ISBLANK(E17)),E17,NOT(ISBLANK(C17)),C17,NOT(ISBLANK(A17)),A17) -> DDD
A18: Базы данных | B18: =AVERAGE(D18:D19) -> 0.2 | C18: noSQL | D18: =F18 -> 0.3 | F18: =M18/N18 -> 0.3 | H18: =M18/N18 -> 0.3 | J18: =M18/N18 -> 0.3 | L18: =M18/N18 -> 0.3 | M18: 3 | N18: 10 | O18: =IFS(NOT(ISBLANK(K18)),K18,NOT(ISBLANK(I18)),I18,NOT(ISBLANK(G18)),G18,NOT(ISBLANK(E18)),E18,NOT(ISBLANK(C18)),C18,NOT(ISBLANK(A18)),A18) -> noSQL
C19: relational | D19: =F19 -> 0.1 | F19: =M19/N19 -> 0.1 | H19: =M19/N19 -> 0.1 | J19: =M19/N19 -> 0.1 | L19: =M19/N19 -> 0.1 | M19: 1 | N19: 10 | O19: =IFS(NOT(ISBLANK(K19)),K19,NOT(ISBLANK(I19)),I19,NOT(ISBLANK(G19)),G19,NOT(ISBLANK(E19)),E19,NOT(ISBLANK(C19)),C19,NOT(ISBLANK(A19)),A19) -> relational
M20: * - где 0 - в первый раз вижу, 10 - чуть ли не сам разработал эту технологию

Sheet Окружение
A1: L0 | C1: L1 | E1: L2 | G1: L3 | I1: L4 | K1: L5 | M1: Уровень | N1: Макс. | O1: Оцениваемый пункт | P1: Комментарий
A2: Инструменты разработки | B2: =AVERAGE(D2:D4) -> 0.56666667 | C2: Itellij | D2: =F2 -> 0.6 | F2: =M2/N2 -> 0.6 | H2: =M2/N2 -> 0.6 | J2: =M2/N2 -> 0.6 | L2: =M2/N2 -> 0.6 | M2: 6 | N2: 10 | O2: =IFS(NOT(ISBLANK(K2)),K2,NOT(ISBLANK(I2)),I2,NOT(ISBLANK(G2)),G2,NOT(ISBLANK(E2)),E2,NOT(ISBLANK(C2)),C2,NOT(ISBLANK(A2)),A2) -> Itellij
C3: VSCode | D3: =F3 -> 0.4 | F3: =M3/N3 -> 0.4 | H3: =M3/N3 -> 0.4 | J3: =M3/N3 -> 0.4 | L3: =M3/N3 -> 0.4 | M3: 4 | N3: 10 | O3: =IFS(NOT(ISBLANK(K3)),K3,NOT(ISBLANK(I3)),I3,NOT(ISBLANK(G3)),G3,NOT(ISBLANK(E3)),E3,NOT(ISBLANK(C3)),C3,NOT(ISBLANK(A3)),A3) -> VSCode
C4: DartPad | D4: =F4 -> 0.7 | F4: =M4/N4 -> 0.7 | H4: =M4/N4 -> 0.7 | J4: =M4/N4 -> 0.7 | L4: =M4/N4 -> 0.7 | M4: 7 | N4: 10 | O4: =IFS(NOT(ISBLANK(K4)),K4,NOT(ISBLANK(I4)),I4,NOT(ISBLANK(G4)),G4,NOT(ISBLANK(E4)),E4,NOT(ISBLANK(C4)),C4,NOT(ISBLANK(A4)),A4) -> DartPad
A5: Cli | B5: =D5 -> 0.4 | D5: =F5 -> 0.4 | F5: =M5/N5 -> 0.4 | H5: =M5/N5 -> 0.4 | J5: =M5/N5 -> 0.4 | L5: =M5/N5 -> 0.4 | M5: 4 | N5: 10 | O5: =IFS(NOT(ISBLANK(K5)),K5,NOT(ISBLANK(I5)),I5,NOT(ISBLANK(G5)),G5,NOT(ISBLANK(E5)),E5,NOT(ISBLANK(C5)),C5,NOT(ISBLANK(A5)),A5) -> Cli
A6: Git | B6: =D6 -> 0.6 | D6: =F6 -> 0.6 | F6: =M6/N6 -> 0.6 | H6: =M6/N6 -> 0.6 | J6: =M6/N6 -> 0.6 | L6: =M6/N6 -> 0.6 | M6: 6 | N6: 10 | O6: =IFS(NOT(ISBLANK(K6)),K6,NOT(ISBLANK(I6)),I6,NOT(ISBLANK(G6)),G6,NOT(ISBLANK(E6)),E6,NOT(ISBLANK(C6)),C6,NOT(ISBLANK(A6)),A6) -> Git
A7: ci/cd | B7: =AVERAGE(D7:D11) -> 0.04 | C7: Github Actions | D7: =F7 -> 0.1 | F7: =M7/N7 -> 0.1 | H7: =M7/N7 -> 0.1 | J7: =M7/N7 -> 0.1 | L7: =M7/N7 -> 0.1 | M7: 1 | N7: 10 | O7: =IFS(NOT(ISBLANK(K7)),K7,NOT(ISBLANK(I7)),I7,NOT(ISBLANK(G7)),G7,NOT(ISBLANK(E7)),E7,NOT(ISBLANK(C7)),C7,NOT(ISBLANK(A7)),A7) -> Github Actions
C8: Codemagic | D8: =F8 -> 0.1 | F8: =M8/N8 -> 0.1 | H8: =M8/N8 -> 0.1 | J8: =M8/N8 -> 0.1 | L8: =M8/N8 -> 0.1 | M8: 1 | N8: 10 | O8: =IFS(NOT(ISBLANK(K8)),K8,NOT(ISBLANK(I8)),I8,NOT(ISBLANK(G8)),G8,NOT(ISBLANK(E8)),E8,NOT(ISBLANK(C8)),C8,NOT(ISBLANK(A8)),A8) -> Codemagic
C9: Appcircle | D9: =F9 -> 0 | F9: =M9/N9 -> 0 | H9: =M9/N9 -> 0 | J9: =M9/N9 -> 0 | L9: =M9/N9 -> 0 | M9: 0 | N9: 10 | O9: =IFS(NOT(ISBLANK(K9)),K9,NOT(ISBLANK(I9)),I9,NOT(ISBLANK(G9)),G9,NOT(ISBLANK(E9)),E9,NOT(ISBLANK(C9)),C9,NOT(ISBLANK(A9)),A9) -> Appcircle
C10: Bitrise | D10: =F10 -> 0 | F10: =M10/N10 -> 0 | H10: =M10/N10 -> 0 | J10: =M10/N10 -> 0 | L10: =M10/N10 -> 0 | M10: 0 | N10: 10 | O10: =IFS(NOT(ISBLANK(K10)),K10,NOT(ISBLANK(I10)),I10,NOT(ISBLANK(G10)),G10,NOT(ISBLANK(E10)),E10,NOT(ISBLANK(C10)),C10,NOT(ISBLANK(A10)),A10) -> Bitrise
C11: Fastlane | D11: =F11 -> 0 | F11: =M11/N11 -> 0 | H11: =M11/N11 -> 0 | J11: =M11/N11 -> 0 | L11: =M11/N11 -> 0 | M11: 0 | N11: 10 | O11: =IFS(NOT(ISBLANK(K11)),K11,NOT(ISBLANK(I11)),I11,NOT(ISBLANK(G11)),G11,NOT(ISBLANK(E11)),E11,NOT(ISBLANK(C11)),C11,NOT(ISBLANK(A11)),A11) -> Fastlane
A12: анализаторы | B12: =AVERAGE(D12:D14) -> 0.33333333 | C12: настройка правил | D12: =F12 -> 0.9 | F12: =M12/N12 -> 0.9 | H12: =M12/N12 -> 0.9 | J12: =M12/N12 -> 0.9 | L12: =M12/N12 -> 0.9 | M12: 9 | N12: 10 | O12: =IFS(NOT(ISBLANK(K12)),K12,NOT(ISBLANK(I12)),I12,NOT(ISBLANK(G12)),G12,NOT(ISBLANK(E12)),E12,NOT(ISBLANK(C12)),C12,NOT(ISBLANK(A12)),A12) -> настройка правил
C13: разработка правил | D13: =F13 -> 0 | F13: =M13/N13 -> 0 | H13: =M13/N13 -> 0 | J13: =M13/N13 -> 0 | L13: =M13/N13 -> 0 | M13: 0 | N13: 10 | O13: =IFS(NOT(ISBLANK(K13)),K13,NOT(ISBLANK(I13)),I13,NOT(ISBLANK(G13)),G13,NOT(ISBLANK(E13)),E13,NOT(ISBLANK(C13)),C13,NOT(ISBLANK(A13)),A13) -> разработка правил
C14: нативные анализаторы | D14: =F14 -> 0.1 | F14: =M14/N14 -> 0.1 | H14: =M14/N14 -> 0.1 | J14: =M14/N14 -> 0.1 | L14: =M14/N14 -> 0.1 | M14: 1 | N14: 10 | O14: =IFS(NOT(ISBLANK(K14)),K14,NOT(ISBLANK(I14)),I14,NOT(ISBLANK(G14)),G14,NOT(ISBLANK(E14)),E14,NOT(ISBLANK(C14)),C14,NOT(ISBLANK(A14)),A14) -> нативные анализаторы
A15: платформенная разработка | B15: =AVERAGE(D15:D20) -> 0.11666667 | C15: Android | D15: =F15 -> 0.2 | F15: =M15/N15 -> 0.2 | H15: =M15/N15 -> 0.2 | J15: =M15/N15 -> 0.2 | L15: =M15/N15 -> 0.2 | M15: 2 | N15: 10 | O15: =IFS(NOT(ISBLANK(K15)),K15,NOT(ISBLANK(I15)),I15,NOT(ISBLANK(G15)),G15,NOT(ISBLANK(E15)),E15,NOT(ISBLANK(C15)),C15,NOT(ISBLANK(A15)),A15) -> Android
C16: iOS | D16: =F16 -> 0 | F16: =M16/N16 -> 0 | H16: =M16/N16 -> 0 | J16: =M16/N16 -> 0 | L16: =M16/N16 -> 0 | M16: 0 | N16: 10 | O16: =IFS(NOT(ISBLANK(K16)),K16,NOT(ISBLANK(I16)),I16,NOT(ISBLANK(G16)),G16,NOT(ISBLANK(E16)),E16,NOT(ISBLANK(C16)),C16,NOT(ISBLANK(A16)),A16) -> iOS
C17: macOS | D17: =F17 -> 0 | F17: =M17/N17 -> 0 | H17: =M17/N17 -> 0 | J17: =M17/N17 -> 0 | L17: =M17/N17 -> 0 | M17: 0 | N17: 10 | O17: =IFS(NOT(ISBLANK(K17)),K17,NOT(ISBLANK(I17)),I17,NOT(ISBLANK(G17)),G17,NOT(ISBLANK(E17)),E17,NOT(ISBLANK(C17)),C17,NOT(ISBLANK(A17)),A17) -> macOS
C18: Windows | D18: =F18 -> 0.2 | F18: =M18/N18 -> 0.2 | H18: =M18/N18 -> 0.2 | J18: =M18/N18 -> 0.2 | L18: =M18/N18 -> 0.2 | M18: 2 | N18: 10 | O18: =IFS(NOT(ISBLANK(K18)),K18,NOT(ISBLANK(I18)),I18,NOT(ISBLANK(G18)),G18,NOT(ISBLANK(E18)),E18,NOT(ISBLANK(C18)),C18,NOT(ISBLANK(A18)),A18) -> Windows
C19: Linux | D19: =F19 -> 0 | F19: =M19/N19 -> 0 | H19: =M19/N19 -> 0 | J19: =M19/N19 -> 0 | L19: =M19/N19 -> 0 | M19: 0 | N19: 10 | O19: =IFS(NOT(ISBLANK(K19)),K19,NOT(ISBLANK(I19)),I19,NOT(ISBLANK(G19)),G19,NOT(ISBLANK(E19)),E19,NOT(ISBLANK(C19)),C19,NOT(ISBLANK(A19)),A19) -> Linux
C20: Web | D20: =F20 -> 0.3 | F20: =M20/N20 -> 0.3 | H20: =M20/N20 -> 0.3 | J20: =M20/N20 -> 0.3 | L20: =M20/N20 -> 0.3 | M20: 3 | N20: 10 | O20: =IFS(NOT(ISBLANK(K20)),K20,NOT(ISBLANK(I20)),I20,NOT(ISBLANK(G20)),G20,NOT(ISBLANK(E20)),E20,NOT(ISBLANK(C20)),C20,NOT(ISBLANK(A20)),A20) -> Web
A21: backend | B21: =D21 -> 0.1 | D21: =F21 -> 0.1 | F21: =M21/N21 -> 0.1 | H21: =M21/N21 -> 0.1 | J21: =M21/N21 -> 0.1 | L21: =M21/N21 -> 0.1 | M21: 1 | N21: 10 | O21: =IFS(NOT(ISBLANK(K21)),K21,NOT(ISBLANK(I21)),I21,NOT(ISBLANK(G21)),G21,NOT(ISBLANK(E21)),E21,NOT(ISBLANK(C21)),C21,NOT(ISBLANK(A21)),A21) -> backend
A22: Rest | B22: =D22 -> 0.9 | D22: =F22 -> 0.9 | F22: =M22/N22 -> 0.9 | H22: =M22/N22 -> 0.9 | J22: =M22/N22 -> 0.9 | L22: =M22/N22 -> 0.9 | M22: 9 | N22: 10 | O22: =IFS(NOT(ISBLANK(K22)),K22,NOT(ISBLANK(I22)),I22,NOT(ISBLANK(G22)),G22,NOT(ISBLANK(E22)),E22,NOT(ISBLANK(C22)),C22,NOT(ISBLANK(A22)),A22) -> Rest
A23: Grafql | B23: =D23 -> 0 | D23: =F23 -> 0 | F23: =M23/N23 -> 0 | H23: =M23/N23 -> 0 | J23: =M23/N23 -> 0 | L23: =M23/N23 -> 0 | M23: 0 | N23: 10 | O23: =IFS(NOT(ISBLANK(K23)),K23,NOT(ISBLANK(I23)),I23,NOT(ISBLANK(G23)),G23,NOT(ISBLANK(E23)),E23,NOT(ISBLANK(C23)),C23,NOT(ISBLANK(A23)),A23) -> Grafql
A24: swagger | B24: =D24 -> 0.1 | D24: =F24 -> 0.1 | F24: =M24/N24 -> 0.1 | H24: =M24/N24 -> 0.1 | J24: =M24/N24 -> 0.1 | L24: =M24/N24 -> 0.1 | M24: 1 | N24: 10 | O24: =IFS(NOT(ISBLANK(K24)),K24,NOT(ISBLANK(I24)),I24,NOT(ISBLANK(G24)),G24,NOT(ISBLANK(E24)),E24,NOT(ISBLANK(C24)),C24,NOT(ISBLANK(A24)),A24) -> swagger
A25: Stores | B25: =AVERAGE(D25:D29) -> 0.3 | C25: Appstore | D25: =F25 -> 0.8 | F25: =M25/N25 -> 0.8 | H25: =M25/N25 -> 0.8 | J25: =M25/N25 -> 0.8 | L25: =M25/N25 -> 0.8 | M25: 8 | N25: 10 | O25: =IFS(NOT(ISBLANK(K25)),K25,NOT(ISBLANK(I25)),I25,NOT(ISBLANK(G25)),G25,NOT(ISBLANK(E25)),E25,NOT(ISBLANK(C25)),C25,NOT(ISBLANK(A25)),A25) -> Appstore
C26: Google Play | D26: =F26 -> 0.7 | F26: =M26/N26 -> 0.7 | H26: =M26/N26 -> 0.7 | J26: =M26/N26 -> 0.7 | L26: =M26/N26 -> 0.7 | M26: 7 | N26: 10 | O26: =IFS(NOT(ISBLANK(K26)),K26,NOT(ISBLANK(I26)),I26,NOT(ISBLANK(G26)),G26,NOT(ISBLANK(E26)),E26,NOT(ISBLANK(C26)),C26,NOT(ISBLANK(A26)),A26) -> Google Play
C27: Xiaomi Market | D27: =F27 -> 0 | F27: =M27/N27 -> 0 | H27: =M27/N27 -> 0 | J27: =M27/N27 -> 0 | L27: =M27/N27 -> 0 | M27: 0 | N27: 10 | O27: =IFS(NOT(ISBLANK(K27)),K27,NOT(ISBLANK(I27)),I27,NOT(ISBLANK(G27)),G27,NOT(ISBLANK(E27)),E27,NOT(ISBLANK(C27)),C27,NOT(ISBLANK(A27)),A27) -> Xiaomi Market
C28: AppGallery | D28: =F28 -> 0 | F28: =M28/N28 -> 0 | H28: =M28/N28 -> 0 | J28: =M28/N28 -> 0 | L28: =M28/N28 -> 0 | M28: 0 | N28: 10 | O28: =IFS(NOT(ISBLANK(K28)),K28,NOT(ISBLANK(I28)),I28,NOT(ISBLANK(G28)),G28,NOT(ISBLANK(E28)),E28,NOT(ISBLANK(C28)),C28,NOT(ISBLANK(A28)),A28) -> AppGallery
C29: Samsung Galaxy Store | D29: =F29 -> 0 | F29: =M29/N29 -> 0 | H29: =M29/N29 -> 0 | J29: =M29/N29 -> 0 | L29: =M29/N29 -> 0 | M29: 0 | N29: 10 | O29: =IFS(NOT(ISBLANK(K29)),K29,NOT(ISBLANK(I29)),I29,NOT(ISBLANK(G29)),G29,NOT(ISBLANK(E29)),E29,NOT(ISBLANK(C29)),C29,NOT(ISBLANK(A29)),A29) -> Samsung Galaxy Store
A30: Firebase | B30: =D30 -> 0.3 | D30: =F30 -> 0.3 | F30: =M30/N30 -> 0.3 | H30: =M30/N30 -> 0.3 | J30: =M30/N30 -> 0.3 | L30: =M30/N30 -> 0.3 | M30: 3 | N30: 10 | O30: =IFS(NOT(ISBLANK(K30)),K30,NOT(ISBLANK(I30)),I30,NOT(ISBLANK(G30)),G30,NOT(ISBLANK(E30)),E30,NOT(ISBLANK(C30)),C30,NOT(ISBLANK(A30)),A30) -> Firebase
A31: Design | B31: =AVERAGE(D31:D33) -> 0.16666667 | C31: HIG | D31: =F31 -> 0.1 | F31: =M31/N31 -> 0.1 | H31: =M31/N31 -> 0.1 | J31: =M31/N31 -> 0.1 | L31: =M31/N31 -> 0.1 | M31: 1 | N31: 10 | O31: =IFS(NOT(ISBLANK(K31)),K31,NOT(ISBLANK(I31)),I31,NOT(ISBLANK(G31)),G31,NOT(ISBLANK(E31)),E31,NOT(ISBLANK(C31)),C31,NOT(ISBLANK(A31)),A31) -> HIG
C32: Material | D32: =F32 -> 0.3 | F32: =M32/N32 -> 0.3 | H32: =M32/N32 -> 0.3 | J32: =M32/N32 -> 0.3 | L32: =M32/N32 -> 0.3 | M32: 3 | N32: 10 | O32: =IFS(NOT(ISBLANK(K32)),K32,NOT(ISBLANK(I32)),I32,NOT(ISBLANK(G32)),G32,NOT(ISBLANK(E32)),E32,NOT(ISBLANK(C32)),C32,NOT(ISBLANK(A32)),A32) -> Material
C33: Material You | D33: =F33 -> 0.1 | F33: =M33/N33 -> 0.1 | H33: =M33/N33 -> 0.1 | J33: =M33/N33 -> 0.1 | L33: =M33/N33 -> 0.1 | M33: 1 | N33: 10 | O33: =IFS(NOT(ISBLANK(K33)),K33,NOT(ISBLANK(I33)),I33,NOT(ISBLANK(G33)),G33,NOT(ISBLANK(E33)),E33,NOT(ISBLANK(C33)),C33,NOT(ISBLANK(A33)),A33) -> Material You
A34: разработка плагинов/скриптов | B34: =D34 -> 0.1 | D34: =F34 -> 0.1 | F34: =M34/N34 -> 0.1 | H34: =M34/N34 -> 0.1 | J34: =M34/N34 -> 0.1 | L34: =M34/N34 -> 0.1 | M34: 1 | N34: 10 | O34: =IFS(NOT(ISBLANK(K34)),K34,NOT(ISBLANK(I34)),I34,NOT(ISBLANK(G34)),G34,NOT(ISBLANK(E34)),E34,NOT(ISBLANK(C34)),C34,NOT(ISBLANK(A34)),A34) -> разработка плагинов/скриптов
A35: дополнительные языки | B35: =AVERAGE(D35:D39) -> 0.28 | C35: Kotlin | D35: =F35 -> 0.1 | F35: =M35/N35 -> 0.1 | H35: =M35/N35 -> 0.1 | J35: =M35/N35 -> 0.1 | L35: =M35/N35 -> 0.1 | M35: 1 | N35: 10 | O35: =IFS(NOT(ISBLANK(K35)),K35,NOT(ISBLANK(I35)),I35,NOT(ISBLANK(G35)),G35,NOT(ISBLANK(E35)),E35,NOT(ISBLANK(C35)),C35,NOT(ISBLANK(A35)),A35) -> Kotlin
C36: Java | D36: =F36 -> 0.3 | F36: =M36/N36 -> 0.3 | H36: =M36/N36 -> 0.3 | J36: =M36/N36 -> 0.3 | L36: =M36/N36 -> 0.3 | M36: 3 | N36: 10 | O36: =IFS(NOT(ISBLANK(K36)),K36,NOT(ISBLANK(I36)),I36,NOT(ISBLANK(G36)),G36,NOT(ISBLANK(E36)),E36,NOT(ISBLANK(C36)),C36,NOT(ISBLANK(A36)),A36) -> Java
C37: Objective C | D37: =F37 -> 0 | F37: =M37/N37 -> 0 | H37: =M37/N37 -> 0 | J37: =M37/N37 -> 0 | L37: =M37/N37 -> 0 | M37: 0 | N37: 10 | O37: =IFS(NOT(ISBLANK(K37)),K37,NOT(ISBLANK(I37)),I37,NOT(ISBLANK(G37)),G37,NOT(ISBLANK(E37)),E37,NOT(ISBLANK(C37)),C37,NOT(ISBLANK(A37)),A37) -> Objective C
C38: Swift | D38: =F38 -> 0 | F38: =M38/N38 -> 0 | H38: =M38/N38 -> 0 | J38: =M38/N38 -> 0 | L38: =M38/N38 -> 0 | M38: 0 | N38: 10 | O38: =IFS(NOT(ISBLANK(K38)),K38,NOT(ISBLANK(I38)),I38,NOT(ISBLANK(G38)),G38,NOT(ISBLANK(E38)),E38,NOT(ISBLANK(C38)),C38,NOT(ISBLANK(A38)),A38) -> Swift
C39: другие | D39: =F39 -> 1 | F39: =M39/N39 -> 1 | H39: =M39/N39 -> 1 | J39: =M39/N39 -> 1 | L39: =M39/N39 -> 1 | M39: 1 | N39: 1 | O39: =IFS(NOT(ISBLANK(K39)),K39,NOT(ISBLANK(I39)),I39,NOT(ISBLANK(G39)),G39,NOT(ISBLANK(E39)),E39,NOT(ISBLANK(C39)),C39,NOT(ISBLANK(A39)),A39) -> другие
A40: профилирование | B40: =D40 -> 0.3 | D40: =F40 -> 0.3 | F40: =M40/N40 -> 0.3 | H40: =M40/N40 -> 0.3 | J40: =M40/N40 -> 0.3 | L40: =M40/N40 -> 0.3 | M40: 3 | N40: 10 | O40: =IFS(NOT(ISBLANK(K40)),K40,NOT(ISBLANK(I40)),I40,NOT(ISBLANK(G40)),G40,NOT(ISBLANK(E40)),E40,NOT(ISBLANK(C40)),C40,NOT(ISBLANK(A40)),A40) -> профилирование
...

Sheet Тестрирование
A1: L0 | C1: L1 | E1: L2 | G1: L3 | I1: L4 | K1: L5 | M1: Уровень | N1: Макс. | O1: Оцениваемый пункт | P1: Комментарий
A2: Подходы | B2: =D2 -> 0.2 | C2: TDD | D2: =F2 -> 0.2 | F2: =M2/N2 -> 0.2 | H2: =M2/N2 -> 0.2 | J2: =M2/N2 -> 0.2 | L2: =M2/N2 -> 0.2 | M2: 2 | N2: 10 | O2: =IFS(NOT(ISBLANK(K2)),K2,NOT(ISBLANK(I2)),I2,NOT(ISBLANK(G2)),G2,NOT(ISBLANK(E2)),E2,NOT(ISBLANK(C2)),C2,NOT(ISBLANK(A2)),A2) -> TDD
A3: Написание тестов | B3: =AVERAGE(D3:D5) -> 0.13333333 | C3: unit | D3: =F3 -> 0.2 | F3: =M3/N3 -> 0.2 | H3: =M3/N3 -> 0.2 | J3: =M3/N3 -> 0.2 | L3: =M3/N3 -> 0.2 | M3: 2 | N3: 10 | O3: =IFS(NOT(ISBLANK(K3)),K3,NOT(ISBLANK(I3)),I3,NOT(ISBLANK(G3)),G3,NOT(ISBLANK(E3)),E3,NOT(ISBLANK(C3)),C3,NOT(ISBLANK(A3)),A3) -> unit
C4: golden | D4: =F4 -> 0.1 | F4: =M4/N4 -> 0.1 | H4: =M4/N4 -> 0.1 | J4: =M4/N4 -> 0.1 | L4: =M4/N4 -> 0.1 | M4: 1 | N4: 10 | O4: =IFS(NOT(ISBLANK(K4)),K4,NOT(ISBLANK(I4)),I4,NOT(ISBLANK(G4)),G4,NOT(ISBLANK(E4)),E4,NOT(ISBLANK(C4)),C4,NOT(ISBLANK(A4)),A4) -> golden
C5: e2e | D5: =F5 -> 0.1 | F5: =M5/N5 -> 0.1 | H5: =M5/N5 -> 0.1 | J5: =M5/N5 -> 0.1 | L5: =M5/N5 -> 0.1 | M5: 1 | N5: 10 | O5: =IFS(NOT(ISBLANK(K5)),K5,NOT(ISBLANK(I5)),I5,NOT(ISBLANK(G5)),G5,NOT(ISBLANK(E5)),E5,NOT(ISBLANK(C5)),C5,NOT(ISBLANK(A5)),A5) -> e2e
A6: flutter специфичные | B6: =D6 -> 0.1 | C6: widget test | D6: =F6 -> 0.1 | F6: =M6/N6 -> 0.1 | H6: =M6/N6 -> 0.1 | J6: =M6/N6 -> 0.1 | L6: =M6/N6 -> 0.1 | M6: 1 | N6: 10 | O6: =IFS(NOT(ISBLANK(K6)),K6,NOT(ISBLANK(I6)),I6,NOT(ISBLANK(G6)),G6,NOT(ISBLANK(E6)),E6,NOT(ISBLANK(C6)),C6,NOT(ISBLANK(A6)),A6) -> widget test

Sheet Teamwork
A1: L0 | C1: L1 | E1: L2 | G1: L3 | I1: L4 | K1: L5 | M1: Уровень | N1: Макс. | O1: Оцениваемый пункт | P1: Комментарий
A2: Code Review | B2: =D2 -> 0.5 | D2: =F2 -> 0.5 | F2: =M2/N2 -> 0.5 | H2: =M2/N2 -> 0.5 | J2: =M2/N2 -> 0.5 | L2: =M2/N2 -> 0.5 | M2: 5 | N2: 10 | O2: =IFS(NOT(ISBLANK(K2)),K2,NOT(ISBLANK(I2)),I2,NOT(ISBLANK(G2)),G2,NOT(ISBLANK(E2)),E2,NOT(ISBLANK(C2)),C2,NOT(ISBLANK(A2)),A2) -> Code Review
A3: Менторство | B3: =D3 -> 0.5 | D3: =F3 -> 0.5 | F3: =M3/N3 -> 0.5 | H3: =M3/N3 -> 0.5 | J3: =M3/N3 -> 0.5 | L3: =M3/N3 -> 0.5 | M3: 5 | N3: 10 | O3: =IFS(NOT(ISBLANK(K3)),K3,NOT(ISBLANK(I3)),I3,NOT(ISBLANK(G3)),G3,NOT(ISBLANK(E3)),E3,NOT(ISBLANK(C3)),C3,NOT(ISBLANK(A3)),A3) -> Менторство

Sheet Dart
A1: L0 | C1: L1 | E1: L2 | G1: L3 | I1: L4 | K1: L5 | M1: Уровень | N1: Макс. | O1: Оцениваемый пункт | P1: Комментарий
A2: Типизация | B2: =AVERAGE(D2:D5) -> 0.8 | C2: Система типов языка | D2: =AVERAGE(F2:F4) -> 0.8 | E2: до NullSafety | F2: =M2/N2 -> 0.8 | H2: =M2/N2 -> 0.8 | J2: =M2/N2 -> 0.8 | L2: =M2/N2 -> 0.8 | M2: 8 | N2: 10 | O2: =IFS(NOT(ISBLANK(K2)),K2,NOT(ISBLANK(I2)),I2,NOT(ISBLANK(G2)),G2,NOT(ISBLANK(E2)),E2,NOT(ISBLANK(C2)),C2,NOT(ISBLANK(A2)),A2) -> до NullSafety
E3: NullSafety | F3: =AVERAGE(H3:H4) -> 0.8 | G3: Sound | H3: =M3/N3 -> 0.8 | J3: =M3/N3 -> 0.8 | L3: =M3/N3 -> 0.8 | M3: 8 | N3: 10 | O3: =IFS(NOT(ISBLANK(K3)),K3,NOT(ISBLANK(I3)),I3,NOT(ISBLANK(G3)),G3,NOT(ISBLANK(E3)),E3,NOT(ISBLANK(C3)),C3,NOT(ISBLANK(A3)),A3) -> Sound
G4: Unsound | H4: =M4/N4 -> 0.8 | J4: =M4/N4 -> 0.8 | L4: =M4/N4 -> 0.8 | M4: 8 | N4: 10 | O4: =IFS(NOT(ISBLANK(K4)),K4,NOT(ISBLANK(I4)),I4,NOT(ISBLANK(G4)),G4,NOT(ISBLANK(E4)),E4,NOT(ISBLANK(C4)),C4,NOT(ISBLANK(A4)),A4) -> Unsound
C5: dynamic | D5: =F5 -> 0.8 | F5: =M5/N5 -> 0.8 | H5: =M5/N5 -> 0.8 | J5: =M5/N5 -> 0.8 | L5: =M5/N5 -> 0.8 | M5: 8 | N5: 10 | O5: =IFS(NOT(ISBLANK(K5)),K5,NOT(ISBLANK(I5)),I5,NOT(ISBLANK(G5)),G5,NOT(ISBLANK(E5)),E5,NOT(ISBLANK(C5)),C5,NOT(ISBLANK(A5)),A5) -> dynamic
A6: Асинхронность | B6: =AVERAGE(D6:D10) -> 0.62 | C6: Future | D6: =F6 -> 0.8 | F6: =M6/N6 -> 0.8 | H6: =M6/N6 -> 0.8 | J6: =M6/N6 -> 0.8 | L6: =M6/N6 -> 0.8 | M6: 8 | N6: 10 | O6: =IFS(NOT(ISBLANK(K6)),K6,NOT(ISBLANK(I6)),I6,NOT(ISBLANK(G6)),G6,NOT(ISBLANK(E6)),E6,NOT(ISBLANK(C6)),C6,NOT(ISBLANK(A6)),A6) -> Future
C7: asnync/await | D7: =F7 -> 0.8 | F7: =M7/N7 -> 0.8 | H7: =M7/N7 -> 0.8 | J7: =M7/N7 -> 0.8 | L7: =M7/N7 -> 0.8 | M7: 8 | N7: 10 | O7: =IFS(NOT(ISBLANK(K7)),K7,NOT(ISBLANK(I7)),I7,NOT(ISBLANK(G7)),G7,NOT(ISBLANK(E7)),E7,NOT(ISBLANK(C7)),C7,NOT(ISBLANK(A7)),A7) -> asnync/await
C8: microtask | D8: =F8 -> 0.3 | F8: =M8/N8 -> 0.3 | H8: =M8/N8 -> 0.3 | J8: =M8/N8 -> 0.3 | L8: =M8/N8 -> 0.3 | M8: 3 | N8: 10 | O8: =IFS(NOT(ISBLANK(K8)),K8,NOT(ISBLANK(I8)),I8,NOT(ISBLANK(G8)),G8,NOT(ISBLANK(E8)),E8,NOT(ISBLANK(C8)),C8,NOT(ISBLANK(A8)),A8) -> microtask
C9: eventloop | D9: =F9 -> 0.5 | F9: =M9/N9 -> 0.5 | H9: =M9/N9 -> 0.5 | J9: =M9/N9 -> 0.5 | L9: =M9/N9 -> 0.5 | M9: 5 | N9: 10 | O9: =IFS(NOT(ISBLANK(K9)),K9,NOT(ISBLANK(I9)),I9,NOT(ISBLANK(G9)),G9,NOT(ISBLANK(E9)),E9,NOT(ISBLANK(C9)),C9,NOT(ISBLANK(A9)),A9) -> eventloop
C10: Stream | D10: =F10 -> 0.7 | F10: =M10/N10 -> 0.7 | H10: =M10/N10 -> 0.7 | J10: =M10/N10 -> 0.7 | L10: =M10/N10 -> 0.7 | M10: 7 | N10: 10 | O10: =IFS(NOT(ISBLANK(K10)),K10,NOT(ISBLANK(I10)),I10,NOT(ISBLANK(G10)),G10,NOT(ISBLANK(E10)),E10,NOT(ISBLANK(C10)),C10,NOT(ISBLANK(A10)),A10) -> Stream
A11: Параллельность | B11: =D11 -> 0.3 | C11: Isolate | D11: =F11 -> 0.3 | F11: =M11/N11 -> 0.3 | H11: =M11/N11 -> 0.3 | J11: =M11/N11 -> 0.3 | L11: =M11/N11 -> 0.3 | M11: 3 | N11: 10 | O11: =IFS(NOT(ISBLANK(K11)),K11,NOT(ISBLANK(I11)),I11,NOT(ISBLANK(G11)),G11,NOT(ISBLANK(E11)),E11,NOT(ISBLANK(C11)),C11,NOT(ISBLANK(A11)),A11) -> Isolate
A12: Концепты | B12: =AVERAGE(D12:D19) -> 0.6625 | C12: Object | D12: =F12 -> 1 | F12: =M12/N12 -> 1 | H12: =M12/N12 -> 1 | J12: =M12/N12 -> 1 | L12: =M12/N12 -> 1 | M12: 10 | N12: 10 | O12: =IFS(NOT(ISBLANK(K12)),K12,NOT(ISBLANK(I12)),I12,NOT(ISBLANK(G12)),G12,NOT(ISBLANK(E12)),E12,NOT(ISBLANK(C12)),C12,NOT(ISBLANK(A12)),A12) -> Object
C13: infer types | D13: =F13 -> 0.5 | F13: =M13/N13 -> 0.5 | H13: =M13/N13 -> 0.5 | J13: =M13/N13 -> 0.5 | L13: =M13/N13 -> 0.5 | M13: 5 | N13: 10 | O13: =IFS(NOT(ISBLANK(K13)),K13,NOT(ISBLANK(I13)),I13,NOT(ISBLANK(G13)),G13,NOT(ISBLANK(E13)),E13,NOT(ISBLANK(C13)),C13,NOT(ISBLANK(A13)),A13) -> infer types
C14: NullSafety | D14: =F14 -> 0.8 | F14: =M14/N14 -> 0.8 | H14: =M14/N14 -> 0.8 | J14: =M14/N14 -> 0.8 | L14: =M14/N14 -> 0.8 | M14: 8 | N14: 10 | O14: =IFS(NOT(ISBLANK(K14)),K14,NOT(ISBLANK(I14)),I14,NOT(ISBLANK(G14)),G14,NOT(ISBLANK(E14)),E14,NOT(ISBLANK(C14)),C14,NOT(ISBLANK(A14)),A14) -> NullSafety
C15: dynamic | D15: =F15 -> 0.7 | F15: =M15/N15 -> 0.7 | H15: =M15/N15 -> 0.7 | J15: =M15/N15 -> 0.7 | L15: =M15/N15 -> 0.7 | M15: 7 | N15: 10 | O15: =IFS(NOT(ISBLANK(K15)),K15,NOT(ISBLANK(I15)),I15,NOT(ISBLANK(G15)),G15,NOT(ISBLANK(E15)),E15,NOT(ISBLANK(C15)),C15,NOT(ISBLANK(A15)),A15) -> dynamic
C16: Generic | D16: =F16 -> 0.5 | F16: =M16/N16 -> 0.5 | H16: =M16/N16 -> 0.5 | J16: =M16/N16 -> 0.5 | L16: =M16/N16 -> 0.5 | M16: 5 | N16: 10 | O16: =IFS(NOT(ISBLANK(K16)),K16,NOT(ISBLANK(I16)),I16,NOT(ISBLANK(G16)),G16,NOT(ISBLANK(E16)),E16,NOT(ISBLANK(C16)),C16,NOT(ISBLANK(A16)),A16) -> Generic
C17: visibility | D17: =F17 -> 0.7 | F17: =M17/N17 -> 0.7 | H17: =M17/N17 -> 0.7 | J17: =M17/N17 -> 0.7 | L17: =M17/N17 -> 0.7 | M17: 7 | N17: 10 | O17: =IFS(NOT(ISBLANK(K17)),K17,NOT(ISBLANK(I17)),I17,NOT(ISBLANK(G17)),G17,NOT(ISBLANK(E17)),E17,NOT(ISBLANK(C17)),C17,NOT(ISBLANK(A17)),A17) -> visibility
C18: error/warning(code) | D18: =F18 -> 0.6 | F18: =M18/N18 -> 0.6 | H18: =M18/N18 -> 0.6 | J18: =M18/N18 -> 0.6 | L18: =M18/N18 -> 0.6 | M18: 6 | N18: 10 | O18: =IFS(NOT(ISBLANK(K18)),K18,NOT(ISBLANK(I18)),I18,NOT(ISBLANK(G18)),G18,NOT(ISBLANK(E18)),E18,NOT(ISBLANK(C18)),C18,NOT(ISBLANK(A18)),A18) -> error/warning(code)
C19: error/exception(runtime) | D19: =F19 -> 0.5 | F19: =M19/N19 -> 0.5 | H19: =M19/N19 -> 0.5 | J19: =M19/N19 -> 0.5 | L19: =M19/N19 -> 0.5 | M19: 5 | N19: 10 | O19: =IFS(NOT(ISBLANK(K19)),K19,NOT(ISBLANK(I19)),I19,NOT(ISBLANK(G19)),G19,NOT(ISBLANK(E19)),E19,NOT(ISBLANK(C19)),C19,NOT(ISBLANK(A19)),A19) -> error/exception(runtime)
A20: Callable | B20: =D20 -> 0.1 | D20: =F20 -> 0.1 | F20: =M20/N20 -> 0.1 | H20: =M20/N20 -> 0.1 | J20: =M20/N20 -> 0.1 | L20: =M20/N20 -> 0.1 | M20: 1 | N20: 10 | O20: =IFS(NOT(ISBLANK(K20)),K20,NOT(ISBLANK(I20)),I20,NOT(ISBLANK(G20)),G20,NOT(ISBLANK(E20)),E20,NOT(ISBLANK(C20)),C20,NOT(ISBLANK(A20)),A20) -> Callable
A21: Generators | B21: =D21 -> 0.2 | D21: =F21 -> 0.2 | F21: =M21/N21 -> 0.2 | H21: =M21/N21 -> 0.2 | J21: =M21/N21 -> 0.2 | L21: =M21/N21 -> 0.2 | M21: 2 | N21: 10 | O21: =IFS(NOT(ISBLANK(K21)),K21,NOT(ISBLANK(I21)),I21,NOT(ISBLANK(G21)),G21,NOT(ISBLANK(E21)),E21,NOT(ISBLANK(C21)),C21,NOT(ISBLANK(A21)),A21) -> Generators
A22: Typedefs | B22: =D22 -> 0 | D22: =F22 -> 0 | F22: =M22/N22 -> 0 | H22: =M22/N22 -> 0 | J22: =M22/N22 -> 0 | L22: =M22/N22 -> 0 | M22: 0 | N22: 10 | O22: =IFS(NOT(ISBLANK(K22)),K22,NOT(ISBLANK(I22)),I22,NOT(ISBLANK(G22)),G22,NOT(ISBLANK(E22)),E22,NOT(ISBLANK(C22)),C22,NOT(ISBLANK(A22)),A22) -> Typedefs
A23: Metadata | B23: =D23 -> 0.2 | D23: =F23 -> 0.2 | F23: =M23/N23 -> 0.2 | H23: =M23/N23 -> 0.2 | J23: =M23/N23 -> 0.2 | L23: =M23/N23 -> 0.2 | M23: 2 | N23: 10 | O23: =IFS(NOT(ISBLANK(K23)),K23,NOT(ISBLANK(I23)),I23,NOT(ISBLANK(G23)),G23,NOT(ISBLANK(E23)),E23,NOT(ISBLANK(C23)),C23,NOT(ISBLANK(A23)),A23) -> Metadata
A24: Устройство языка | B24: =AVERAGE(D24:D25) -> 0.2 | C24: Dart VM | D24: =F24 -> 0.2 | F24: =M24/N24 -> 0.2 | H24: =M24/N24 -> 0.2 | J24: =M24/N24 -> 0.2 | L24: =M24/N24 -> 0.2 | M24: 2 | N24: 10 | O24: =IFS(NOT(ISBLANK(K24)),K24,NOT(ISBLANK(I24)),I24,NOT(ISBLANK(G24)),G24,NOT(ISBLANK(E24)),E24,NOT(ISBLANK(C24)),C24,NOT(ISBLANK(A24)),A24) -> Dart VM
C25: компиляция | D25: =F25 -> 0.2 | F25: =M25/N25 -> 0.2 | H25: =M25/N25 -> 0.2 | J25: =M25/N25 -> 0.2 | L25: =M25/N25 -> 0.2 | M25: 2 | N25: 10 | O25: =IFS(NOT(ISBLANK(K25)),K25,NOT(ISBLANK(I25)),I25,NOT(ISBLANK(G25)),G25,NOT(ISBLANK(E25)),E25,NOT(ISBLANK(C25)),C25,NOT(ISBLANK(A25)),A25) -> компиляция
A26: ffi | B26: =D26 -> 0.1 | D26: =F26 -> 0.1 | F26: =M26/N26 -> 0.1 | H26: =M26/N26 -> 0.1 | J26: =M26/N26 -> 0.1 | L26: =M26/N26 -> 0.1 | M26: 1 | N26: 10 | O26: =IFS(NOT(ISBLANK(K26)),K26,NOT(ISBLANK(I26)),I26,NOT(ISBLANK(G26)),G26,NOT(ISBLANK(E26)),E26,NOT(ISBLANK(C26)),C26,NOT(ISBLANK(A26)),A26) -> ffi

Sheet Flutter
A1: L0 | C1: L1 | E1: L2 | G1: L3 | I1: L4 | K1: L5 | M1: Уровень | N1: Макс. | O1: Оцениваемый пункт | P1: Комментарий
A2: Устройство | B2: =AVERAGE(D2:D23) -> 0.27216117 | C2: Потоки | D2: =F2 -> 0.1 | F2: =M2/N2 -> 0.1 | H2: =M2/N2 -> 0.1 | J2: =M2/N2 -> 0.1 | L2: =M2/N2 -> 0.1 | M2: 1 | N2: 10 | O2: =IFS(NOT(ISBLANK(K2)),K2,NOT(ISBLANK(I2)),I2,NOT(ISBLANK(G2)),G2,NOT(ISBLANK(E2)),E2,NOT(ISBLANK(C2)),C2,NOT(ISBLANK(A2)),A2) -> Потоки
C3: Глобальные слои | D3: =F3 -> 0.1 | F3: =M3/N3 -> 0.1 | H3: =M3/N3 -> 0.1 | J3: =M3/N3 -> 0.1 | L3: =M3/N3 -> 0.1 | M3: 1 | N3: 10 | O3: =IFS(NOT(ISBLANK(K3)),K3,NOT(ISBLANK(I3)),I3,NOT(ISBLANK(G3)),G3,NOT(ISBLANK(E3)),E3,NOT(ISBLANK(C3)),C3,NOT(ISBLANK(A3)),A3) -> Глобальные слои
C4: SKIA | D4: =F4 -> 0.1 | F4: =M4/N4 -> 0.1 | H4: =M4/N4 -> 0.1 | J4: =M4/N4 -> 0.1 | L4: =M4/N4 -> 0.1 | M4: 1 | N4: 10 | O4: =IFS(NOT(ISBLANK(K4)),K4,NOT(ISBLANK(I4)),I4,NOT(ISBLANK(G4)),G4,NOT(ISBLANK(E4)),E4,NOT(ISBLANK(C4)),C4,NOT(ISBLANK(A4)),A4) -> SKIA
C5: Bindings | D5: =F5 -> 0.1 | F5: =M5/N5 -> 0.1 | H5: =M5/N5 -> 0.1 | J5: =M5/N5 -> 0.1 | L5: =M5/N5 -> 0.1 | M5: 1 | N5: 10 | O5: =IFS(NOT(ISBLANK(K5)),K5,NOT(ISBLANK(I5)),I5,NOT(ISBLANK(G5)),G5,NOT(ISBLANK(E5)),E5,NOT(ISBLANK(C5)),C5,NOT(ISBLANK(A5)),A5) -> Bindings
C6: Цикл построения кадра | D6: =F6 -> 0.4 | F6: =M6/N6 -> 0.4 | H6: =M6/N6 -> 0.4 | J6: =M6/N6 -> 0.4 | L6: =M6/N6 -> 0.4 | M6: 4 | N6: 10 | O6: =IFS(NOT(ISBLANK(K6)),K6,NOT(ISBLANK(I6)),I6,NOT(ISBLANK(G6)),G6,NOT(ISBLANK(E6)),E6,NOT(ISBLANK(C6)),C6,NOT(ISBLANK(A6)),A6) -> Цикл построения кадра
C7: Деревья | D7: =F7 -> 0.3 | F7: =M7/N7 -> 0.3 | H7: =M7/N7 -> 0.3 | J7: =M7/N7 -> 0.3 | L7: =M7/N7 -> 0.3 | M7: 3 | N7: 10 | O7: =IFS(NOT(ISBLANK(K7)),K7,NOT(ISBLANK(I7)),I7,NOT(ISBLANK(G7)),G7,NOT(ISBLANK(E7)),E7,NOT(ISBLANK(C7)),C7,NOT(ISBLANK(A7)),A7) -> Деревья
C8: context | D8: =F8 -> 0.4 | F8: =M8/N8 -> 0.4 | H8: =M8/N8 -> 0.4 | J8: =M8/N8 -> 0.4 | L8: =M8/N8 -> 0.4 | M8: 4 | N8: 10 | O8: =IFS(NOT(ISBLANK(K8)),K8,NOT(ISBLANK(I8)),I8,NOT(ISBLANK(G8)),G8,NOT(ISBLANK(E8)),E8,NOT(ISBLANK(C8)),C8,NOT(ISBLANK(A8)),A8) -> context
C9: RenderObject | D9: =F9 -> 0.3 | F9: =M9/N9 -> 0.3 | H9: =M9/N9 -> 0.3 | J9: =M9/N9 -> 0.3 | L9: =M9/N9 -> 0.3 | M9: 3 | N9: 10 | O9: =IFS(NOT(ISBLANK(K9)),K9,NOT(ISBLANK(I9)),I9,NOT(ISBLANK(G9)),G9,NOT(ISBLANK(E9)),E9,NOT(ISBLANK(C9)),C9,NOT(ISBLANK(A9)),A9) -> RenderObject
C10: Sliver | D10: =F10 -> 0.5 | F10: =M10/N10 -> 0.5 | H10: =M10/N10 -> 0.5 | J10: =M10/N10 -> 0.5 | L10: =M10/N10 -> 0.5 | M10: 5 | N10: 10 | O10: =IFS(NOT(ISBLANK(K10)),K10,NOT(ISBLANK(I10)),I10,NOT(ISBLANK(G10)),G10,NOT(ISBLANK(E10)),E10,NOT(ISBLANK(C10)),C10,NOT(ISBLANK(A10)),A10) -> Sliver
C11: Widget | D11: =AVERAGE(F11:F14) -> 0.36666667 | E11: Component | F11: =AVERAGE(H11:H13) -> 0.63333333 | G11: Stateless | H11: =M11/N11 -> 0.8 | J11: =M11/N11 -> 0.8 | L11: =M11/N11 -> 0.8 | M11: 8 | N11: 10 | O11: =IFS(NOT(ISBLANK(K11)),K11,NOT(ISBLANK(I11)),I11,NOT(ISBLANK(G11)),G11,NOT(ISBLANK(E11)),E11,NOT(ISBLANK(C11)),C11,NOT(ISBLANK(A11)),A11) -> Stateless
G12: Statefull | H12: =M12/N12 -> 0.7 | J12: =M12/N12 -> 0.7 | L12: =M12/N12 -> 0.7 | M12: 7 | N12: 10 | O12: =IFS(NOT(ISBLANK(K12)),K12,NOT(ISBLANK(I12)),I12,NOT(ISBLANK(G12)),G12,NOT(ISBLANK(E12)),E12,NOT(ISBLANK(C12)),C12,NOT(ISBLANK(A12)),A12) -> Statefull
G13: Proxy | H13: =M13/N13 -> 0.4 | I13: InheritedWidget | J13: =M13/N13 -> 0.4 | L13: =M13/N13 -> 0.4 | M13: 4 | N13: 10 | O13: =IFS(NOT(ISBLANK(K13)),K13,NOT(ISBLANK(I13)),I13,NOT(ISBLANK(G13)),G13,NOT(ISBLANK(E13)),E13,NOT(ISBLANK(C13)),C13,NOT(ISBLANK(A13)),A13) -> InheritedWidget
E14: RenderObjectWidget | F14: =M14/N14 -> 0.1 | H14: =M14/N14 -> 0.1 | J14: =M14/N14 -> 0.1 | M14: 1 | N14: 10 | O14: =IFS(NOT(ISBLANK(K14)),K14,NOT(ISBLANK(I14)),I14,NOT(ISBLANK(G14)),G14,NOT(ISBLANK(E14)),E14,NOT(ISBLANK(C14)),C14,NOT(ISBLANK(A14)),A14) -> RenderObjectWidget
C15: Code Design Patterns | D15: =AVERAGE(F15:F21) -> 0.27142857 | E15: Factory | F15: =M15/N15 -> 0.3 | H15: =M15/N15 -> 0.3 | J15: =M15/N15 -> 0.3 | L15: =M15/N15 -> 0.3 | M15: 3 | N15: 10 | O15: =IFS(NOT(ISBLANK(K15)),K15,NOT(ISBLANK(I15)),I15,NOT(ISBLANK(G15)),G15,NOT(ISBLANK(E15)),E15,NOT(ISBLANK(C15)),C15,NOT(ISBLANK(A15)),A15) -> Factory
E16: Builder | F16: =M16/N16 -> 0.3 | H16: =M16/N16 -> 0.3 | J16: =M16/N16 -> 0.3 | L16: =M16/N16 -> 0.3 | M16: 3 | N16: 10 | O16: =IFS(NOT(ISBLANK(K16)),K16,NOT(ISBLANK(I16)),I16,NOT(ISBLANK(G16)),G16,NOT(ISBLANK(E16)),E16,NOT(ISBLANK(C16)),C16,NOT(ISBLANK(A16)),A16) -> Builder
E17: State | F17: =M17/N17 -> 0.3 | H17: =M17/N17 -> 0.3 | J17: =M17/N17 -> 0.3 | L17: =M17/N17 -> 0.3 | M17: 3 | N17: 10 | O17: =IFS(NOT(ISBLANK(K17)),K17,NOT(ISBLANK(I17)),I17,NOT(ISBLANK(G17)),G17,NOT(ISBLANK(E17)),E17,NOT(ISBLANK(C17)),C17,NOT(ISBLANK(A17)),A17) -> State
E18: Observer | F18: =M18/N18 -> 0.4 | H18: =M18/N18 -> 0.4 | J18: =M18/N18 -> 0.4 | L18: =M18/N18 -> 0.4 | M18: 4 | N18: 10 | O18: =IFS(NOT(ISBLANK(K18)),K18,NOT(ISBLANK(I18)),I18,NOT(ISBLANK(G18)),G18,NOT(ISBLANK(E18)),E18,NOT(ISBLANK(C18)),C18,NOT(ISBLANK(A18)),A18) -> Observer
E19: Visitor | F19: =M19/N19 -> 0 | H19: =M19/N19 -> 0 | J19: =M19/N19 -> 0 | L19: =M19/N19 -> 0 | M19: 0 | N19: 10 | O19: =IFS(NOT(ISBLANK(K19)),K19,NOT(ISBLANK(I19)),I19,NOT(ISBLANK(G19)),G19,NOT(ISBLANK(E19)),E19,NOT(ISBLANK(C19)),C19,NOT(ISBLANK(A19)),A19) -> Visitor
E20: Decorator | F20: =M20/N20 -> 0.3 | H20: =M20/N20 -> 0.3 | J20: =M20/N20 -> 0.3 | L20: =M20/N20 -> 0.3 | M20: 3 | N20: 10 | O20: =IFS(NOT(ISBLANK(K20)),K20,NOT(ISBLANK(I20)),I20,NOT(ISBLANK(G20)),G20,NOT(ISBLANK(E20)),E20,NOT(ISBLANK(C20)),C20,NOT(ISBLANK(A20)),A20) -> Decorator
E21: Composite | F21: =M21/N21 -> 0.3 | H21: =M21/N21 -> 0.3 | J21: =M21/N21 -> 0.3 | L21: =M21/N21 -> 0.3 | M21: 3 | N21: 10 | O21: =IFS(NOT(ISBLANK(K21)),K21,NOT(ISBLANK(I21)),I21,NOT(ISBLANK(G21)),G21,NOT(ISBLANK(E21)),E21,NOT(ISBLANK(C21)),C21,NOT(ISBLANK(A21)),A21) -> Composite
C22: Gesture system | D22: =F22 -> 0.4 | F22: =M22/N22 -> 0.4 | H22: =M22/N22 -> 0.4 | J22: =M22/N22 -> 0.4 | L22: =M22/N22 -> 0.4 | M22: 4 | N22: 10 | O22: =IFS(NOT(ISBLANK(K22)),K22,NOT(ISBLANK(I22)),I22,NOT(ISBLANK(G22)),G22,NOT(ISBLANK(E22)),E22,NOT(ISBLANK(C22)),C22,NOT(ISBLANK(A22)),A22) -> Gesture system
C23: Focus system | D23: =F23 -> 0.2 | F23: =M23/N23 -> 0.2 | H23: =M23/N23 -> 0.2 | J23: =M23/N23 -> 0.2 | L23: =M23/N23 -> 0.2 | M23: 2 | N23: 10 | O23: =IFS(NOT(ISBLANK(K23)),K23,NOT(ISBLANK(I23)),I23,NOT(ISBLANK(G23)),G23,NOT(ISBLANK(E23)),E23,NOT(ISBLANK(C23)),C23,NOT(ISBLANK(A23)),A23) -> Focus system
A24: Использование | B24: =AVERAGE(D24:D33) -> 0.38095238 | C24: Widgets | D24: =AVERAGE(F24:F25) -> 0.5 | E24: Material | F24: =M24/N24 -> 0.8 | H24: =M24/N24 -> 0.8 | J24: =M24/N24 -> 0.8 | L24: =M24/N24 -> 0.8 | M24: 8 | N24: 10 | O24: =IFS(NOT(ISBLANK(K24)),K24,NOT(ISBLANK(I24)),I24,NOT(ISBLANK(G24)),G24,NOT(ISBLANK(E24)),E24,NOT(ISBLANK(C24)),C24,NOT(ISBLANK(A24)),A24) -> Material
E25: Cupertino | F25: =M25/N25 -> 0.2 | H25: =M25/N25 -> 0.2 | J25: =M25/N25 -> 0.2 | L25: =M25/N25 -> 0.2 | M25: 2 | N25: 10 | O25: =IFS(NOT(ISBLANK(K25)),K25,NOT(ISBLANK(I25)),I25,NOT(ISBLANK(G25)),G25,NOT(ISBLANK(E25)),E25,NOT(ISBLANK(C25)),C25,NOT(ISBLANK(A25)),A25) -> Cupertino
C26: Animations | D26: =AVERAGE(F26:F28) -> 0.16666667 | E26: implicit | F26: =M26/N26 -> 0.4 | H26: =M26/N26 -> 0.4 | J26: =M26/N26 -> 0.4 | L26: =M26/N26 -> 0.4 | M26: 4 | N26: 10 | O26: =IFS(NOT(ISBLANK(K26)),K26,NOT(ISBLANK(I26)),I26,NOT(ISBLANK(G26)),G26,NOT(ISBLANK(E26)),E26,NOT(ISBLANK(C26)),C26,NOT(ISBLANK(A26)),A26) -> implicit
E27: explicit | F27: =M27/N27 -> 0.1 | H27: =M27/N27 -> 0.1 | J27: =M27/N27 -> 0.1 | L27: =M27/N27 -> 0.1 | M27: 1 | N27: 10 | O27: =IFS(NOT(ISBLANK(K27)),K27,NOT(ISBLANK(I27)),I27,NOT(ISBLANK(G27)),G27,NOT(ISBLANK(E27)),E27,NOT(ISBLANK(C27)),C27,NOT(ISBLANK(A27)),A27) -> explicit
E28: skeleton | F28: =M28/N28 -> 0 | H28: =M28/N28 -> 0 | J28: =M28/N28 -> 0 | L28: =M28/N28 -> 0 | M28: 0 | N28: 10 | O28: =IFS(NOT(ISBLANK(K28)),K28,NOT(ISBLANK(I28)),I28,NOT(ISBLANK(G28)),G28,NOT(ISBLANK(E28)),E28,NOT(ISBLANK(C28)),C28,NOT(ISBLANK(A28)),A28) -> skeleton
C29: Diagnostic | D29: =F29 -> 0.1 | F29: =M29/N29 -> 0.1 | H29: =M29/N29 -> 0.1 | J29: =M29/N29 -> 0.1 | L29: =M29/N29 -> 0.1 | M29: 1 | N29: 10 | O29: =IFS(NOT(ISBLANK(K29)),K29,NOT(ISBLANK(I29)),I29,NOT(ISBLANK(G29)),G29,NOT(ISBLANK(E29)),E29,NOT(ISBLANK(C29)),C29,NOT(ISBLANK(A29)),A29) -> Diagnostic
C30: accesability | D30: =F30 -> 0.2 | F30: =M30/N30 -> 0.2 | H30: =M30/N30 -> 0.2 | J30: =M30/N30 -> 0.2 | L30: =M30/N30 -> 0.2 | M30: 2 | N30: 10 | O30: =IFS(NOT(ISBLANK(K30)),K30,NOT(ISBLANK(I30)),I30,NOT(ISBLANK(G30)),G30,NOT(ISBLANK(E30)),E30,NOT(ISBLANK(C30)),C30,NOT(ISBLANK(A30)),A30) -> accesability
C31: Assets | D31: =F31 -> 0.8 | F31: =M31/N31 -> 0.8 | H31: =M31/N31 -> 0.8 | J31: =M31/N31 -> 0.8 | L31: =M31/N31 -> 0.8 | M31: 8 | N31: 10 | O31: =IFS(NOT(ISBLANK(K31)),K31,NOT(ISBLANK(I31)),I31,NOT(ISBLANK(G31)),G31,NOT(ISBLANK(E31)),E31,NOT(ISBLANK(C31)),C31,NOT(ISBLANK(A31)),A31) -> Assets
C32: Layout | D32: =F32 -> 0.6 | F32: =M32/N32 -> 0.6 | H32: =M32/N32 -> 0.6 | J32: =M32/N32 -> 0.6 | L32: =M32/N32 -> 0.6 | M32: 6 | N32: 10 | O32: =IFS(NOT(ISBLANK(K32)),K32,NOT(ISBLANK(I32)),I32,NOT(ISBLANK(G32)),G32,NOT(ISBLANK(E32)),E32,NOT(ISBLANK(C32)),C32,NOT(ISBLANK(A32)),A32) -> Layout
C33: Theme | D33: =F33 -> 0.3 | F33: =M33/N33 -> 0.3 | H33: =M33/N33 -> 0.3 | J33: =M33/N33 -> 0.3 | L33: =M33/N33 -> 0.3 | M33: 3 | N33: 10 | O33: =IFS(NOT(ISBLANK(K33)),K33,NOT(ISBLANK(I33)),I33,NOT(ISBLANK(G33)),G33,NOT(ISBLANK(E33)),E33,NOT(ISBLANK(C33)),C33,NOT(ISBLANK(A33)),A33) -> Theme
A34: Полезные сторонние решения | B34: =AVERAGE(D34:D51) -> 0.21722222 | C34: Архитектурные либы/стейтменеджеры | D34: =AVERAGE(F34:F38) -> 0.24 | E34: Elementary | F34: =M34/N34 -> 0.5 | H34: =M34/N34 -> 0.5 | J34: =M34/N34 -> 0.5 | L34: =M34/N34 -> 0.5 | M34: 5 | N34: 10 | O34: =IFS(NOT(ISBLANK(K34)),K34,NOT(ISBLANK(I34)),I34,NOT(ISBLANK(G34)),G34,NOT(ISBLANK(E34)),E34,NOT(ISBLANK(C34)),C34,NOT(ISBLANK(A34)),A34) -> Elementary
E35: mwwm | F35: =M35/N35 -> 0.3 | H35: =M35/N35 -> 0.3 | J35: =M35/N35 -> 0.3 | L35: =M35/N35 -> 0.3 | M35: 3 | N35: 10 | O35: =IFS(NOT(ISBLANK(K35)),K35,NOT(ISBLANK(I35)),I35,NOT(ISBLANK(G35)),G35,NOT(ISBLANK(E35)),E35,NOT(ISBLANK(C35)),C35,NOT(ISBLANK(A35)),A35) -> mwwm
E36: MobX | F36: =M36/N36 -> 0 | H36: =M36/N36 -> 0 | J36: =M36/N36 -> 0 | L36: =M36/N36 -> 0 | M36: 0 | N36: 10 | O36: =IFS(NOT(ISBLANK(K36)),K36,NOT(ISBLANK(I36)),I36,NOT(ISBLANK(G36)),G36,NOT(ISBLANK(E36)),E36,NOT(ISBLANK(C36)),C36,NOT(ISBLANK(A36)),A36) -> MobX
E37: bloc/qubit | F37: =M37/N37 -> 0.3 | H37: =M37/N37 -> 0.3 | J37: =M37/N37 -> 0.3 | L37: =M37/N37 -> 0.3 | M37: 3 | N37: 10 | O37: =IFS(NOT(ISBLANK(K37)),K37,NOT(ISBLANK(I37)),I37,NOT(ISBLANK(G37)),G37,NOT(ISBLANK(E37)),E37,NOT(ISBLANK(C37)),C37,NOT(ISBLANK(A37)),A37) -> bloc/qubit
E38: redux | F38: =M38/N38 -> 0.1 | H38: =M38/N38 -> 0.1 | J38: =M38/N38 -> 0.1 | L38: =M38/N38 -> 0.1 | M38: 1 | N38: 10 | O38: =IFS(NOT(ISBLANK(K38)),K38,NOT(ISBLANK(I38)),I38,NOT(ISBLANK(G38)),G38,NOT(ISBLANK(E38)),E38,NOT(ISBLANK(C38)),C38,NOT(ISBLANK(A38)),A38) -> redux
C39: DI | D39: =AVERAGE(F39:F41) -> 0.26666667 | E39: provider | F39: =M39/N39 -> 0.8 | H39: =M39/N39 -> 0.8 | J39: =M39/N39 -> 0.8 | L39: =M39/N39 -> 0.8 | M39: 8 | N39: 10 | O39: =IFS(NOT(ISBLANK(K39)),K39,NOT(ISBLANK(I39)),I39,NOT(ISBLANK(G39)),G39,NOT(ISBLANK(E39)),E39,NOT(ISBLANK(C39)),C39,NOT(ISBLANK(A39)),A39) -> provider
E40: riverpod | F40: =M40/N40 -> 0 | H40: =M40/N40 -> 0 | J40: =M40/N40 -> 0 | L40: =M40/N40 -> 0 | M40: 0 | N40: 10 | O40: =IFS(NOT(ISBLANK(K40)),K40,NOT(ISBLANK(I40)),I40,NOT(ISBLANK(G40)),G40,NOT(ISBLANK(E40)),E40,NOT(ISBLANK(C40)),C40,NOT(ISBLANK(A40)),A40) -> riverpod
...

Sheet Результат
A1: Фундаментальные | B1: =AVERAGE('Фундаментальные'!B2:B19) -> 0.42727273
A2: Окружение | B2: =AVERAGE('Окружение'!B2:B41) -> 0.28843137
A3: Тестирование | B3: =AVERAGE('Тестрирование'!B2:B6) -> 0.14444444
A4: Teamwork | B4: =AVERAGE(Teamwork!B2:B3) -> 0.5
A5: Dart | B5: =AVERAGE(Dart!B2:B26) -> 0.31825
A6: Flutter | B6: =AVERAGE(Flutter!B2:B51) -> 0.29011193
